Workbook

Sheet Comparacao PVBtCalc
A1: ="PVBtCalc — planilha de comparacao (modelo RADIAL, "&$F$6&", "&TEXT($B$13,"0.00")&" C, alvo "&$B$18&" ft)"
A2: AMARELO = voce edita. VERDE = voce digita o que o PVBtCalc mostrou. Branco = calculado.
A4: CONSTANTES | B4: valor | C4: descricao | E4: SELETOR DO CASO DE TESTE | F4: escolha
A5: n | B5: =IFERROR(INDEX('Banco de teste'!$D$6:$D$23,MATCH($F$5&"|"&$F$6,'Banco de teste'!$I$6:$I$23,0)),"") | C5: Fator de area (Tabela 1, via seletor) | E5: Rocha | F5: Indiana Limestone
A6: a | B6: =IFERROR(INDEX('Banco de teste'!$E$6:$E$23,MATCH($F$5&"|"&$F$6,'Banco de teste'!$I$6:$I$23,0)),"") | C6: Coef. zona de permeabilidade (Tabela 1, via seletor) | E6: Sistema acido | F6: HCl com inibidor
A7: b | B7: =IFERROR(INDEX('Banco de teste'!$F$6:$F$23,MATCH($F$5&"|"&$F$6,'Banco de teste'!$I$6:$I$23,0)),"") | C7: Coef. de fluxo do wormhole (Tabela 1, via seletor) | E7: ff da rocha | F7: =IFERROR(INDEX('Banco de teste'!$H$6:$H$23,MATCH($F$5&"|"&$F$6,'Banco de teste'!$I$6:$I$23,0)),"?") | G7: informativo — nao entra no calculo radial hoje
A8: k0 | B8: =IFERROR(INDEX('Banco de teste'!$G$6:$G$23,MATCH($F$5&"|"&$F$6,'Banco de teste'!$I$6:$I$23,0)),"") | C8: Constante estatica (Tabela 1, via seletor) | E8: caso # | F8: =IFERROR(INDEX('Banco de teste'!$A$6:$A$23,MATCH($F$5&"|"&$F$6,'Banco de teste'!$I$6:$I$23,0)),"?")
A9: X | B9: 0.5417 | C9: Poder de dissolucao FIXO. No app X varia com a densidade do acido, logo com T (Eq. 4). | E9: f ja implementado no app? | F9: SIM | G9: mude para SIM depois que o backend passar a aplicar o flowing fraction
A10: L | B10: 1 | C10: Comprimento caracteristico (m) | E10: f aplicado no calculo | F10: =IF($F$9="SIM",$F$7,1) | G10: =IF($F$9="SIM","planilha multiplicando V_A e tbt por f="&TEXT($F$7,"0.00"),"f NAO aplicado (estado atual do app) -- V_A igual para todas as rochas")
A11: M | B11: 60 | C11: Tempo caracteristico, s (constante do artigo)
A12: ENTRADAS | B12: valor | C12: observacao | E12: FLOWRATE SWEEP (use isto no app) | F12: valor
A13: System Temperature (°C) | B13: 60 | C13: A UI e o export usam °C. O modelo calcula em Kelvin — conversao na linha 21. | E13: min [gal/(ft.min)] | F13: 0.09 | G13: sweep default ~ q_opt/10 .. q_opt*10 para o caso acima
A14: Core Porosity | B14: 0.2 | E14: max [gal/(ft.min)] | F14: 9.3
A15: Acid Concentration (w/w) | B15: 0.15 | E15: N pontos | F15: 80
A16: Wellbore Size (in) | B16: 6 | C16: modo DIAMETRO -> raio = 3 in (B22 = B16/2 em polegadas) | E16: passo linear | F16: =(F14-F13)/(F15-1)
A17: Payzone Thickness (ft) | B17: 1
A18: Target (ft) | B18: 10 | C18: comprimento do wormhole
A20: DERIVADOS | B20: valor
A21: T_K [K] (= °C + 273.15) — entra na Eq. 18 | B21: =$B$13+273.15
A22: r_w [m] | B22: =($B$16/2)*0.0254
A23: h_o [m] | B23: =$B$17*0.3048
A24: Dm [m2/s] | B24: =EXP(-2270/$B$21+1.326*$B$15-12.11)
A25: k_eff [1/s] | B25: =$B$8*$B$24
A26: A_o [m2] | B26: =2*PI()*$B$22*$B$23
A27: beta = r_w/L | B27: =$B$22/$B$10
A28: h = h_o/L | B28: =$B$23/$B$10
A29: lambda | B29: =$B$18*0.3048/$B$10
A30: coef alpha | B30: =($B$6*(2*$B$28*PI()*$B$10^2)^$B$5)/($B$26*($B$5+1))
A31: termo expansao | B31: =($B$27+$B$29)^($B$5+1)-$B$27^($B$5+1)
A32: SKIN (nao depende da vazao) | B32: =-LN(($B$22/0.3048+$B$18)/($B$22/0.3048))
A35: CURVA COMPLETA (Simulation Chart)
A36: q0 (gal/(ft.min)) | B36: q_o [m3/s] | C36: dv (m/s) | D36: iv (m/s) | E36: wv (m/s) | F36: 1/Da | G36: K | H36: alpha | I36: V_A [m3] | J36: V_A (gal/ft) | K36: tbt (s) | L36: target | M36: tau (adimensional, Eq. 41)
A37: =$F$13 | B37: =A37*(0.00378541178/60)*$B$17 | C37: =B37/$B$26 | D37: =C37/$B$14 | E37: =C37/($B$6*$B$26^($B$5-1)+$B$7*C37) | F37: =(1/(($B$6/$B$26)*(2*$B$28*PI()*$B$10^2*($B$27+$B$29))^$B$5+$B$7*C37))/G37 | G37: =$B$10*$B$25/C37 | H37: =$B$30*$B$31+$B$7*C37*$B$29 | I37: =IF(G37*H37>700,NA(),$F$10*($B$10*$B$26/($B$15*$B$9))*(EXP(G37*H37)-1)/G37) | J37: =IF(ISNA(I37),NA(),I37*264.172052/$B$17) | K37: =IF(ISNA(I37),NA(),I37/B37) | L37: =$B$18 | M37: =IF(ISNA(K37),NA(),K37/$B$11)
A38: =A37+$F$16 | B38: =A38*(0.00378541178/60)*$B$17 | C38: =B38/$B$26 | D38: =C38/$B$14 | E38: =C38/($B$6*$B$26^($B$5-1)+$B$7*C38) | F38: =(1/(($B$6/$B$26)*(2*$B$28*PI()*$B$10^2*($B$27+$B$29))^$B$5+$B$7*C38))/G38 | G38: =$B$10*$B$25/C38 | H38: =$B$30*$B$31+$B$7*C38*$B$29 | I38: =IF(G38*H38>700,NA(),$F$10*($B$10*$B$26/($B$15*$B$9))*(EXP(G38*H38)-1)/G38) | J38: =IF(ISNA(I38),NA(),I38*264.172052/$B$17) | K38: =IF(ISNA(I38),NA(),I38/B38) | L38: =$B$18 | M38: =IF(ISNA(K38),NA(),K38/$B$11)
A39: =A38+$F$16 | B39: =A39*(0.00378541178/60)*$B$17 | C39: =B39/$B$26 | D39: =C39/$B$14 | E39: =C39/($B$6*$B$26^($B$5-1)+$B$7*C39) | F39: =(1/(($B$6/$B$26)*(2*$B$28*PI()*$B$10^2*($B$27+$B$29))^$B$5+$B$7*C39))/G39 | G39: =$B$10*$B$25/C39 | H39: =$B$30*$B$31+$B$7*C39*$B$29 | I39: =IF(G39*H39>700,NA(),$F$10*($B$10*$B$26/($B$15*$B$9))*(EXP(G39*H39)-1)/G39) | J39: =IF(ISNA(I39),NA(),I39*264.172052/$B$17) | K39: =IF(ISNA(I39),NA(),I39/B39) | L39: =$B$18 | M39: =IF(ISNA(K39),NA(),K39/$B$11)
A40: =A39+$F$16 | B40: =A40*(0.00378541178/60)*$B$17 | C40: =B40/$B$26 | D40: =C40/$B$14 | E40: =C40/($B$6*$B$26^($B$5-1)+$B$7*C40) | F40: =(1/(($B$6/$B$26)*(2*$B$28*PI()*$B$10^2*($B$27+$B$29))^$B$5+$B$7*C40))/G40 | G40: =$B$10*$B$25/C40 | H40: =$B$30*$B$31+$B$7*C40*$B$29 | I40: =IF(G40*H40>700,NA(),$F$10*($B$10*$B$26/($B$15*$B$9))*(EXP(G40*H40)-1)/G40) | J40: =IF(ISNA(I40),NA(),I40*264.172052/$B$17) | K40: =IF(ISNA(I40),NA(),I40/B40) | L40: =$B$18 | M40: =IF(ISNA(K40),NA(),K40/$B$11)
A41: =A40+$F$16 | B41: =A41*(0.00378541178/60)*$B$17 | C41: =B41/$B$26 | D41: =C41/$B$14 | E41: =C41/($B$6*$B$26^($B$5-1)+$B$7*C41) | F41: =(1/(($B$6/$B$26)*(2*$B$28*PI()*$B$10^2*($B$27+$B$29))^$B$5+$B$7*C41))/G41 | G41: =$B$10*$B$25/C41 | H41: =$B$30*$B$31+$B$7*C41*$B$29 | I41: =IF(G41*H41>700,NA(),$F$10*($B$10*$B$26/($B$15*$B$9))*(EXP(G41*H41)-1)/G41) | J41: =IF(ISNA(I41),NA(),I41*264.172052/$B$17) | K41: =IF(ISNA(I41),NA(),I41/B41) | L41: =$B$18 | M41: =IF(ISNA(K41),NA(),K41/$B$11)
A42: =A41+$F$16 | B42: =A42*(0.00378541178/60)*$B$17 | C42: =B42/$B$26 | D42: =C42/$B$14 | E42: =C42/($B$6*$B$26^($B$5-1)+$B$7*C42) | F42: =(1/(($B$6/$B$26)*(2*$B$28*PI()*$B$10^2*($B$27+$B$29))^$B$5+$B$7*C42))/G42 | G42: =$B$10*$B$25/C42 | H42: =$B$30*$B$31+$B$7*C42*$B$29 | I42: =IF(G42*H42>700,NA(),$F$10*($B$10*$B$26/($B$15*$B$9))*(EXP(G42*H42)-1)/G42) | J42: =IF(ISNA(I42),NA(),I42*264.172052/$B$17) | K42: =IF(ISNA(I42),NA(),I42/B42) | L42: =$B$18 | M42: =IF(ISNA(K42),NA(),K42/$B$11)
A43: =A42+$F$16 | B43: =A43*(0.00378541178/60)*$B$17 | C43: =B43/$B$26 | D43: =C43/$B$14 | E43: =C43/($B$6*$B$26^($B$5-1)+$B$7*C43) | F43: =(1/(($B$6/$B$26)*(2*$B$28*PI()*$B$10^2*($B$27+$B$29))^$B$5+$B$7*C43))/G43 | G43: =$B$10*$B$25/C43 | H43: =$B$30*$B$31+$B$7*C43*$B$29 | I43: =IF(G43*H43>700,NA(),$F$10*($B$10*$B$26/($B$15*$B$9))*(EXP(G43*H43)-1)/G43) | J43: =IF(ISNA(I43),NA(),I43*264.172052/$B$17) | K43: =IF(ISNA(I43),NA(),I43/B43) | L43: =$B$18 | M43: =IF(ISNA(K43),NA(),K43/$B$11)
A44: =A43+$F$16 | B44: =A44*(0.00378541178/60)*$B$17 | C44: =B44/$B$26 | D44: =C44/$B$14 | E44: =C44/($B$6*$B$26^($B$5-1)+$B$7*C44) | F44: =(1/(($B$6/$B$26)*(2*$B$28*PI()*$B$10^2*($B$27+$B$29))^$B$5+$B$7*C44))/G44 | G44: =$B$10*$B$25/C44 | H44: =$B$30*$B$31+$B$7*C44*$B$29 | I44: =IF(G44*H44>700,NA(),$F$10*($B$10*$B$26/($B$15*$B$9))*(EXP(G44*H44)-1)/G44) | J44: =IF(ISNA(I44),NA(),I44*264.172052/$B$17) | K44: =IF(ISNA(I44),NA(),I44/B44) | L44: =$B$18 | M44: =IF(ISNA(K44),NA(),K44/$B$11)
...

Sheet Banco de teste
A1: BANCO DE COMBINACOES PARA TESTE — 6 rochas x 3 sistemas acidos = 18 casos
A2: Coeficientes da Tabela 1 (Ali & Ziauddin, 2019). Todas as 6 rochas sao CALCARIO.
A3: Por isso a/b/n/k0 dependem SO do acido -- repetem identicos entre as rochas. A rocha muda apenas o ff.
A5: # | B5: rocha | C5: acido | D5: n | E5: a [(m)^2(1-n)] | F5: b [s/m] | G5: k0 [1/m2] | H5: ff (rocha) | I5: id
A6: 1 | B6: Indiana Limestone | C6: HCl (sem inibidor) | D6: 0.65 | E6: 0.000268 | F6: 17.3 | G6: 24300000 | H6: 1 | I6: Indiana Limestone|HCl (sem inibidor)
A7: 2 | B7: Indiana Limestone | C7: HCl com inibidor | D7: 0.65 | E7: 0.00051 | F7: 35.1 | G7: 2430000 | H7: 1 | I7: Indiana Limestone|HCl com inibidor
A8: 3 | B8: Indiana Limestone | C8: Acido emulsificado | D8: 0.65 | E8: 0.000461 | F8: 15.5 | G8: 28500000 | H8: 1 | I8: Indiana Limestone|Acido emulsificado
A9: 4 | B9: Austin Chalk | C9: HCl (sem inibidor) | D9: 0.65 | E9: 0.000268 | F9: 17.3 | G9: 24300000 | H9: 0.92 | I9: Austin Chalk|HCl (sem inibidor)
A10: 5 | B10: Austin Chalk | C10: HCl com inibidor | D10: 0.65 | E10: 0.00051 | F10: 35.1 | G10: 2430000 | H10: 0.92 | I10: Austin Chalk|HCl com inibidor
A11: 6 | B11: Austin Chalk | C11: Acido emulsificado | D11: 0.65 | E11: 0.000461 | F11: 15.5 | G11: 28500000 | H11: 0.92 | I11: Austin Chalk|Acido emulsificado
A12: 7 | B12: Edwards Yellow | C12: HCl (sem inibidor) | D12: 0.65 | E12: 0.000268 | F12: 17.3 | G12: 24300000 | H12: 0.91 | I12: Edwards Yellow|HCl (sem inibidor)
A13: 8 | B13: Edwards Yellow | C13: HCl com inibidor | D13: 0.65 | E13: 0.00051 | F13: 35.1 | G13: 2430000 | H13: 0.91 | I13: Edwards Yellow|HCl com inibidor
A14: 9 | B14: Edwards Yellow | C14: Acido emulsificado | D14: 0.65 | E14: 0.000461 | F14: 15.5 | G14: 28500000 | H14: 0.91 | I14: Edwards Yellow|Acido emulsificado
A15: 10 | B15: Desert Pink | C15: HCl (sem inibidor) | D15: 0.65 | E15: 0.000268 | F15: 17.3 | G15: 24300000 | H15: 0.75 | I15: Desert Pink|HCl (sem inibidor)
A16: 11 | B16: Desert Pink | C16: HCl com inibidor | D16: 0.65 | E16: 0.00051 | F16: 35.1 | G16: 2430000 | H16: 0.75 | I16: Desert Pink|HCl com inibidor
A17: 12 | B17: Desert Pink | C17: Acido emulsificado | D17: 0.65 | E17: 0.000461 | F17: 15.5 | G17: 28500000 | H17: 0.75 | I17: Desert Pink|Acido emulsificado
... A23: 18 | B23: Edwards White | C23: Acido emulsificado | D23: 0.65 | E23: 0.000461 | F23: 15.5 | G23: 28500000 | H23: 0.52 | I23: Edwards White|Acido emulsificado
A25: COMO USAR
A26: 1. Na aba principal, escolha a rocha (F5) e o acido (F6) nas listas suspensas.
A27: 2. Os coeficientes n/a/b/k0 sao puxados daqui automaticamente -- nao digite a mao.
A28: 3. Rode o mesmo caso no PVBtCalc e cole os resultados nas celulas verdes.
A29: 4. Para varrer os 18 casos: mude os seletores e repita. Esperado ~0.13% de diferenca
A30: (vem do X: planilha usa 0.5417, app usa 0.5424).
A32: O QUE ESPERAR AO TROCAR DE ROCHA:
A33: NADA muda no resultado radial. As 6 rochas sao calcario e compartilham a mesma linha
A34: da Tabela 1 -- confira acima: a/b/n/k0 sao identicos nas 3 linhas de cada acido.
A35: O ff (flowing fraction) difere por rocha, mas hoje NAO entra no modelo radial.
A36: Se um dia entrar, sera como fator multiplicativo em V_A e tau -- entao o V_A de
A37: Edwards White (ff=0.52) ficaria ~metade do de Indiana (ff=1.00).
... A41: q_opt maior, volume diferente. E a unica variavel que realmente move o modelo hoje.
